<?xml version="1.0" encoding="utf-8"?>
<!-- =================================================================================== -->
<!-- |    This document was autogenerated by xacro from mybot.xacro                    | -->
<!-- |    EDITING THIS FILE BY HAND IS NOT RECOMMENDED                                 | -->
<!-- =================================================================================== -->
<robot name="mybot" xmlns:xacro="http://www.ros.org/wiki/xacro">
  <gazebo>
    <plugin filename="libgazebo_ros_diff_drive.so" name="differential_drive_controller">
      <robotNamespace>/</robotNamespace>
      <alwaysOn>true</alwaysOn>
      <legacyMode>false</legacyMode>
      <updateRate>50</updateRate>
      <leftJoint>mybot_left_wheel_hinge</leftJoint>
      <rightJoint>mybot_right_wheel_hinge</rightJoint>
      <wheelSeparation>0.25</wheelSeparation>
      <wheelDiameter>0.2</wheelDiameter>
      <torque>20</torque>
      <commandTopic>mybot_cmd_vel</commandTopic>
      <odometryTopic>mybot_odom</odometryTopic>
      <odometryFrame>odom</odometryFrame>
      <robotBaseFrame>mybot_link</robotBaseFrame>
    </plugin>
  </gazebo>
  <gazebo>
    <plugin filename="libgazebo_ros_p3d.so" name="ground_truth">
      <frameName>map</frameName>
      <bodyName>mybot_chassis</bodyName>
      <topicName>odom</topicName>
      <updateRate>30.0</updateRate>
    </plugin>
  </gazebo>
  <gazebo reference="mybot_chassis">
    <material>Gazebo/Orange</material>
  </gazebo>
  <gazebo reference="caster_wheel">
    <mu1>0.0</mu1>
    <mu2>0.0</mu2>
    <material>Gazebo/Red</material>
  </gazebo>
  <gazebo reference="right_wheel">
    <mu1 value="1.0"/>
    <mu2 value="1.0"/>
    <kp value="10000000.0"/>
    <kd value="1.0"/>
    <fdir1 value="1 0 0"/>
    <material>Gazebo/Black</material>
  </gazebo>
  <gazebo reference="left_wheel">
    <mu1 value="1.0"/>
    <mu2 value="1.0"/>
    <kp value="10000000.0"/>
    <kd value="1.0"/>
    <fdir1 value="1 0 0"/>
    <material>Gazebo/Black</material>
  </gazebo>
  <!-- camera -->
  <gazebo reference="camera_link">
    <sensor name="camera" type="depth">
      <plugin filename="libgazebo_ros_openni_kinect.so" name="kinect_camera_controller">
        <cameraName>camera</cameraName>
        <alwaysOn>true</alwaysOn>
        <updateRate>10</updateRate>
        <imageTopicName>rgb/image_raw</imageTopicName>
        <depthImageTopicName>depth/image_raw</depthImageTopicName>
        <pointCloudTopicName>depth/points</pointCloudTopicName>
        <cameraInfoTopicName>rgb/camera_info</cameraInfoTopicName>
        <depthImageCameraInfoTopicName>depth/camera_info</depthImageCameraInfoTopicName>
        <frameName>camera_link_optical</frameName>
        <baseline>0.1</baseline>
        <distortion_k1>0.0</distortion_k1>
        <distortion_k2>0.0</distortion_k2>
        <distortion_k3>0.0</distortion_k3>
        <distortion_t1>0.0</distortion_t1>
        <distortion_t2>0.0</distortion_t2>
        <pointCloudCutoff>0.4</pointCloudCutoff>
      </plugin>
    </sensor>
  </gazebo>
  <gazebo>
    <plugin filename="libgazebo_ros_control.so" name="gazebo_ros_control">
      <robotNamespace>/mybot</robotNamespace>
      <robotSimType>gazebo_ros_control/DefaultRobotHWSim</robotSimType>
    </plugin>
  </gazebo>
  <gazebo reference="base_link">
    <mu>0</mu>
    <mu2>0</mu2>
    <kp>100000000.0</kp>
    <kd>10000.0</kd>
  </gazebo>
  <material name="black">
    <color rgba="0.0 0.0 0.0 1.0"/>
  </material>
  <material name="blue">
    <color rgba="0.0 0.0 0.8 1.0"/>
  </material>
  <material name="green">
    <color rgba="0.0 0.8 0.0 1.0"/>
  </material>
  <material name="grey">
    <color rgba="0.2 0.2 0.2 1.0"/>
  </material>
  <material name="orange">
    <color rgba="1.0 0.423529411765 0.0392156862745 1.0"/>
  </material>
  <material name="brown">
    <color rgba="0.870588235294 0.811764705882 0.764705882353 1.0"/>
  </material>
  <material name="red">
    <color rgba="0.8 0.0 0.0 1.0"/>
  </material>
  <material name="white">
    <color rgba="1.0 1.0 1.0 1.0"/>
  </material>
  <link name="mybot_link"/>
  <joint name="base_joint" type="fixed">
    <parent link="mybot_link"/>
    <child link="mybot_chassis"/>
  </joint>
  <link name="mybot_chassis">
    <collision>
      <origin rpy="0 0 0" xyz="0 0 0.1"/>
      <geometry>
        <box size="0.4 0.2 0.1"/>
      </geometry>
    </collision>
    <visual>
      <origin rpy="0 0 0" xyz="0 0 0.1"/>
      <geometry>
        <box size="0.4 0.2 0.1"/>
      </geometry>
      <material name="orange"/>
    </visual>
    <inertial>
      <origin rpy="0 0 0" xyz="0 0 0.1"/>
      <mass value="5"/>
      <inertia ixx="0.0208333333333" ixy="0" ixz="0" iyy="0.0708333333333" iyz="0" izz="0.0708333333333"/>
    </inertial>
  </link>
  <joint name="fixed" type="fixed">
    <parent link="mybot_chassis"/>
    <child link="mybot_caster_wheel"/>
  </joint>
  <link name="mybot_caster_wheel">
    <collision>
      <origin rpy="0 0 0" xyz="-0.15 0 0.05"/>
      <geometry>
        <sphere radius="0.05"/>
      </geometry>
    </collision>
    <visual>
      <origin rpy="0 0 0" xyz="-0.15 0 0.05"/>
      <geometry>
        <sphere radius="0.05"/>
      </geometry>
      <material name="white"/>
    </visual>
    <inertial>
      <origin rpy="0 0 0" xyz="-0.15 0 0.05"/>
      <mass value="3"/>
      <inertia ixx="0.003" ixy="0" ixz="0" iyy="0.003" iyz="0" izz="0.003"/>
    </inertial>
  </link>
  <link name="mybot_left_wheel">
    <collision>
      <origin rpy="0 1.57079632679 1.57079632679" xyz="0 0 0"/>
      <geometry>
        <cylinder length="0.05" radius="0.1"/>
      </geometry>
    </collision>
    <visual>
      <origin rpy="0 1.57079632679 1.57079632679" xyz="0 0 0"/>
      <geometry>
        <cylinder length="0.05" radius="0.1"/>
      </geometry>
      <material name="white"/>
    </visual>
    <inertial>
      <origin rpy="0 1.57079632679 1.57079632679" xyz="0 0 0"/>
      <mass value="2"/>
      <inertia ixx="0.00541666666667" ixy="0" ixz="0" iyy="0.00541666666667" iyz="0" izz="0.01"/>
    </inertial>
  </link>
  <joint name="mybot_left_wheel_hinge" type="continuous">
    <parent link="mybot_chassis"/>
    <child link="mybot_left_wheel"/>
    <origin rpy="0 0 0" xyz="0.0 0.125 0.1"/>
    <axis rpy="0 0 0" xyz="0 1 0"/>
    <limit effort="100" velocity="100"/>
    <joint_properties damping="0.0" friction="0.0"/>
  </joint>
  <transmission name="left_trans">
    <type>transmission_interface/SimpleTransmission</type>
    <joint name="mybot_left_wheel_hinge">
      <hardwareInterface>EffortJointInterface</hardwareInterface>
    </joint>
    <actuator name="leftMotor">
      <hardwareInterface>EffortJointInterface</hardwareInterface>
      <mechanicalReduction>1</mechanicalReduction>
    </actuator>
  </transmission>
  <link name="mybot_right_wheel">
    <collision>
      <origin rpy="0 1.57079632679 1.57079632679" xyz="0 0 0"/>
      <geometry>
        <cylinder length="0.05" radius="0.1"/>
      </geometry>
    </collision>
    <visual>
      <origin rpy="0 1.57079632679 1.57079632679" xyz="0 0 0"/>
      <geometry>
        <cylinder length="0.05" radius="0.1"/>
      </geometry>
      <material name="white"/>
    </visual>
    <inertial>
      <origin rpy="0 1.57079632679 1.57079632679" xyz="0 0 0"/>
      <mass value="2"/>
      <inertia ixx="0.00541666666667" ixy="0" ixz="0" iyy="0.00541666666667" iyz="0" izz="0.01"/>
    </inertial>
  </link>
  <joint name="mybot_right_wheel_hinge" type="continuous">
    <parent link="mybot_chassis"/>
    <child link="mybot_right_wheel"/>
    <origin rpy="0 0 0" xyz="0.0 -0.125 0.1"/>
    <axis rpy="0 0 0" xyz="0 1 0"/>
    <limit effort="100" velocity="100"/>
    <joint_properties damping="0.0" friction="0.0"/>
  </joint>
  <transmission name="right_trans">
    <type>transmission_interface/SimpleTransmission</type>
    <joint name="mybot_right_wheel_hinge">
      <hardwareInterface>EffortJointInterface</hardwareInterface>
    </joint>
    <actuator name="rightMotor">
      <hardwareInterface>EffortJointInterface</hardwareInterface>
      <mechanicalReduction>1</mechanicalReduction>
    </actuator>
  </transmission>
  <!-- Camera -->
  <link name="camera_link">
    <collision>
      <origin rpy="0 0 0" xyz="0 0 0"/>
      <geometry>
        <box size="0.05 0.05 0.05"/>
      </geometry>
    </collision>
    <visual>
      <origin rpy="0 0 0" xyz="0 0 0"/>
      <geometry>
        <!--<mesh filename="package://gazebo_models/camera.dae" />-->
        <box size="0.05 0.05 0.05"/>
      </geometry>
    </visual>
    <inertial>
      <mass value="0.1"/>
      <inertia ixx="4.16666666667e-05" ixy="0" ixz="0" iyy="4.16666666667e-05" iyz="0" izz="4.16666666667e-05"/>
    </inertial>
  </link>
  <joint name="camera_joint" type="continuous">
    <axis xyz="0 0 1"/>
    <origin rpy="0 0 0" xyz="0.1 0 0.175"/>
    <parent link="mybot_chassis"/>
    <child link="camera_link"/>
    <limit effort="10" lower="-1.57079632679" upper="1.57079632679" velocity="3"/>
  </joint>
  <!-- generate an optical frame http://www.ros.org/reps/rep-0103.html#suffix-frames
      so that ros and opencv can operate on the camera frame correctly -->
  <joint name="camera_optical_joint" type="fixed">
    <!-- these values have to be these values otherwise the gazebo camera image
        won't be aligned properly with the frame it is supposedly originating from -->
    <origin rpy="-1.5708 0 -1.5708" xyz="0 0 0"/>
    <parent link="camera_link"/>
    <child link="camera_link_optical"/>
  </joint>
  <link name="camera_link_optical">
  </link>
  <transmission name="camera_trans">
    <type>transmission_interface/SimpleTransmission</type>
    <joint name="camera_joint">
      <hardwareInterface>PositionJointInterface</hardwareInterface>
    </joint>
    <actuator name="cameraMotor">
      <mechanicalReduction>1</mechanicalReduction>
    </actuator>
  </transmission>
</robot>

